<?xml version="1.0" encoding="utf-8"?>
<!-- This URDF was automatically created by SolidWorks to URDF Exporter! Originally created by Stephen Brawner (brawner@gmail.com) 
     Commit Version: 1.6.0-4-g7f85cfe  Build Version: 1.6.7995.38578
     For more information, please see http://wiki.ros.org/sw_urdf_exporter -->
<robot
  name="spm-asm-v6-2">
  <link
    name="body">
    <inertial>
      <origin
        xyz="-0.000447494654153479 0.331321949812791 0.000113603452558181"
        rpy="0 0 0" />
      <mass
        value="1.52483078220958" />
      <inertia
        ixx="0.00829246519516177"
        ixy="-1.02325386659498E-05"
        ixz="-1.46763239266088E-05"
        iyy="0.00411784045329585"
        iyz="1.16891867374721E-05"
        izz="0.00454099279717948" />
    </inertial>
    <visual>
      <origin
        xyz="0 0 0"
        rpy="0 0 0" />
      <geometry>
        <mesh
          filename="/home/afarah/Documents/UML/willis/rluff/isaac_flapper/Flapper-Env/resources/spm-asm-v6-2/meshes/body.obj" />
      </geometry>
      <material
        name="">
        <color
          rgba="0.752941176470588 0.752941176470588 0.752941176470588 1" />
      </material>
    </visual>
    <collision>
      <origin
        xyz="0 0 0"
        rpy="0 0 0" />
      <geometry>
        <mesh
          filename="/home/afarah/Documents/UML/willis/rluff/isaac_flapper/Flapper-Env/resources/spm-asm-v6-2/meshes/body.obj" />
      </geometry>
    </collision>
  </link>
  <link
    name="egg">
    <inertial>
      <origin
        xyz="-0.000704379747724138 0.000189398528617443 -0.000359342631638893"
        rpy="0 0 0" />
      <mass
        value="0.547069589420612" />
      <inertia
        ixx="0.00058970882866789"
        ixy="-3.36983548502265E-11"
        ixz="0.000147288742365131"
        iyy="0.00078676358354829"
        iyz="2.54054054923086E-11"
        izz="0.000367447759294177" />
    </inertial>
    <visual>
      <origin
        xyz="0 0 0"
        rpy="0 0 0" />
      <geometry>
        <mesh
          filename="/home/afarah/Documents/UML/willis/rluff/isaac_flapper/Flapper-Env/resources/spm-asm-v6-2/meshes/egg.obj" />
      </geometry>
      <material
        name="">
        <color
          rgba="0.752941176470588 0.752941176470588 0.752941176470588 1" />
      </material>
    </visual>
    <collision>
      <origin
        xyz="0 0 0"
        rpy="0 0 0" />
      <geometry>
        <mesh
          filename="/home/afarah/Documents/UML/willis/rluff/isaac_flapper/Flapper-Env/resources/spm-asm-v6-2/meshes/egg.obj" />
      </geometry>
    </collision>
  </link>
  <joint
    name="egg"
    type="continuous">
    <origin
      xyz="0 0.329999999999998 0"
      rpy="-0.00420723995770047 0.477191572872437 -1.5727286634525" />
    <parent
      link="body" />
    <child
      link="egg" />
    <axis
      xyz="0 1 0" />
    <limit
      lower="-1.309"
      upper="1.309"
      effort="0.02"
      velocity="3.927" />
  </joint>
  <link
    name="left">
    <inertial>
      <origin
        xyz="0.141367161453231 0.00171132316628048 -0.014590850978999"
        rpy="0 0 0" />
      <mass
        value="0.200066504276197" />
      <inertia
        ixx="0.000134612037974116"
        ixy="-2.5790330046864E-06"
        ixz="4.07586793565832E-05"
        iyy="0.000409569178120027"
        iyz="6.01341515016151E-08"
        izz="0.000525220739609295" />
    </inertial>
    <visual>
      <origin
        xyz="0 0 0"
        rpy="0 0 0" />
      <geometry>
        <mesh
          filename="/home/afarah/Documents/UML/willis/rluff/isaac_flapper/Flapper-Env/resources/spm-asm-v6-2/meshes/left.obj" />
      </geometry>
      <material
        name="">
        <color
          rgba="0.752941176470588 0.752941176470588 0.752941176470588 1" />
      </material>
    </visual>
    <collision>
      <origin
        xyz="0 0 0"
        rpy="0 0 0" />
      <geometry>
        <mesh
          filename="/home/afarah/Documents/UML/willis/rluff/isaac_flapper/Flapper-Env/resources/spm-asm-v6-2/meshes/left.obj" />
      </geometry>
    </collision>
  </link>
  <joint
    name="left"
    type="continuous">
    <origin
      xyz="0 0 0"
      rpy="-0.475749659218756 -0.0946287475069281 1.61943985488628" />
    <parent
      link="egg" />
    <child
      link="left" />
    <axis
      xyz="0 1 0" />
    <limit
      lower="-0.7854"
      upper="0.7854"
      effort="0.2"
      velocity="1" />
  </joint>
  <link
    name="right">
    <inertial>
      <origin
        xyz="0.141695531960741 -0.00358600947070542 -0.0074884373073913"
        rpy="0 0 0" />
      <mass
        value="0.194771332746872" />
      <inertia
        ixx="0.000130632084466426"
        ixy="4.73968118262733E-07"
        ixz="2.10122124731785E-05"
        iyy="0.000408641338136673"
        iyz="1.79083527905633E-07"
        izz="0.000526701570510772" />
    </inertial>
    <visual>
      <origin
        xyz="0 0 0"
        rpy="0 0 0" />
      <geometry>
        <mesh
          filename="/home/afarah/Documents/UML/willis/rluff/isaac_flapper/Flapper-Env/resources/spm-asm-v6-2/meshes/right.obj" />
      </geometry>
      <material
        name="">
        <color
          rgba="0.752941176470588 0.752941176470588 0.752941176470588 1" />
      </material>
    </visual>
    <collision>
      <origin
        xyz="0 0 0"
        rpy="0 0 0" />
      <geometry>
        <mesh
          filename="/home/afarah/Documents/UML/willis/rluff/isaac_flapper/Flapper-Env/resources/spm-asm-v6-2/meshes/right.obj" />
      </geometry>
    </collision>
  </link>
  <joint
    name="right"
    type="continuous">
    <origin
      xyz="0 -0.000499993016276486 0"
      rpy="0.473964872692399 -0.0449871922540274 -1.59386125890353" />
    <parent
      link="egg" />
    <child
      link="right" />
    <axis
      xyz="0 1 0" />
    <limit
      lower="-0.7854"
      upper="0.7854"
      effort="0.2"
      velocity="1" />
  </joint>
  <link
    name="IMU">
    <inertial>
      <origin
        xyz="-0.000799994413222308 2.98978479086753E-06 0"
        rpy="0 0 0" />
      <mass
        value="0.000677984" />
      <inertia
        ixx="5.05346817122322E-08"
        ixy="-6.35206498663212E-11"
        ixz="-3.35265884718929E-26"
        iyy="3.35383228376594E-08"
        iyz="-5.90699045829493E-24"
        izz="1.7286106833904E-08" />
    </inertial>
    <visual>
      <origin
        xyz="0 0 0"
        rpy="0 0 0" />
      <geometry>
        <mesh
          filename="/home/afarah/Documents/UML/willis/rluff/isaac_flapper/Flapper-Env/resources/spm-asm-v6-2/meshes/IMU.obj" />
      </geometry>
      <material
        name="">
        <color
          rgba="0.792156862745098 0.819607843137255 0.933333333333333 1" />
      </material>
    </visual>
    <collision>
      <origin
        xyz="0 0 0"
        rpy="0 0 0" />
      <geometry>
        <mesh
          filename="/home/afarah/Documents/UML/willis/rluff/isaac_flapper/Flapper-Env/resources/spm-asm-v6-2/meshes/IMU.obj" />
      </geometry>
    </collision>
  </link>
  <joint
    name="IMU"
    type="fixed">
    <origin
      xyz="0.000799994413223405 0.0691941882985599 0"
      rpy="1.5707963267949 0 0" />
    <parent
      link="body" />
    <child
      link="IMU" />
    <axis
      xyz="0 0 0" />
  </joint>
</robot>