<?xml version="1.0" encoding="utf-8"?>
<!-- This URDF was automatically created by SolidWorks to URDF Exporter! Originally created by Stephen Brawner (brawner@gmail.com) 
     Commit Version: 1.6.0-4-g7f85cfe  Build Version: 1.6.7995.38578
     For more information, please see http://wiki.ros.org/sw_urdf_exporter -->
<robot
  name="Glider_S_UI">
  <link
    name="base_link">
    <inertial>
      <origin
        xyz="1.4385E-06 3.3646E-07 3.6467E-06"
        rpy="0 0 0" />
      <mass
        value="6.4021" />
      <inertia
        ixx="0.40729"
        ixy="-1.3561E-06"
        ixz="-0.010981"
        iyy="0.1337"
        iyz="-2.0777E-06"
        izz="0.52299" />
    </inertial>
    <visual>
      <origin
        xyz="0 0 0"
        rpy="0 0 0" />
      <geometry>
        <mesh
          filename="../meshes/base_link.STL" />
      </geometry>
      <material
        name="Plane_Mat">
        <color
          rgba="0.79216 0.81961 0.93333 1" />
      </material>
    </visual>
    <collision>
      <origin
        xyz="0 0 0"
        rpy="0 0 0" />
      <geometry>
        <mesh
          filename="../meshes/base_link.STL" />
      </geometry>
    </collision>
  </link>
  <link
    name="Speedometer1">
    <visual>
      <origin
        xyz="0 0 0"
        rpy="0 0 0" />
      <geometry>
        <mesh
          filename="../meshes/Speedometer1.STL" />
      </geometry>
      <material
        name="S1_Mat">
        <color
          rgba="0 0.85 0.35 1" />
      </material>
    </visual>
  </link>
  <joint
    name="Base_2_S1"
    type="fixed">
    <origin
      xyz="0.0690674218762038 -1.2500011445781 -0.0962555780744807"
      rpy="0 0 0" />
    <parent
      link="base_link" />
    <child
      link="Speedometer1" />
    <axis
      xyz="0 0 0" />
  </joint>
  <link
    name="S1_dial">
    <visual>
      <origin
        xyz="0 0 0"
        rpy="0 0 0" />
      <geometry>
        <mesh
          filename="../meshes/S1_dial.STL" />
      </geometry>
      <material
        name="Dial_Mat">
        <color
          rgba="0.79216 0.81961 0.93333 1" />
      </material>
    </visual>
  </link>
  <joint
    name="S1_axis"
    type="revolute">
    <origin
      xyz="0 0 0"
      rpy="0 0 0" />
    <parent
      link="Speedometer1" />
    <child
      link="S1_dial" />
    <axis
      xyz="-1 0 0" />
    <limit
      lower="0"
      upper="5"
      effort="1"
      velocity="1" />
  </joint>
  <link
    name="Speedometer2">
    <visual>
      <origin
        xyz="0 0 0"
        rpy="0 0 0" />
      <geometry>
        <mesh
          filename="../meshes/Speedometer2.STL" />
      </geometry>
      <material
        name="S2_Mat">
        <color
          rgba="0 .35 .8 1" />
      </material>
    </visual>
  </link>
  <joint
    name="Base_2_S2"
    type="fixed">
    <origin
      xyz="0.0690674218762038 1.2499988554219 -0.096255578074481"
      rpy="0 0 0" />
    <parent
      link="base_link" />
    <child
      link="Speedometer2" />
    <axis
      xyz="0 0 0" />
  </joint>
  <link
    name="S2_dial">
    <visual>
      <origin
        xyz="0 0 0"
        rpy="0 0 0" />
      <geometry>
        <mesh
          filename="../meshes/S2_dial.STL" />
      </geometry>
      <material
        name="Dial_Mat">
        <color
          rgba="0.79216 0.81961 0.93333 1" />
      </material>
    </visual>
  </link>
  <joint
    name="S2_axis"
    type="revolute">
    <origin
      xyz="0 0 0"
      rpy="0 0 0" />
    <parent
      link="Speedometer2" />
    <child
      link="S2_dial" />
    <axis
      xyz="-1 0 0" />
    <limit
      lower="0"
      upper="5"
      effort="1"
      velocity="1" />
  </joint>
  <link
    name="Altimeter">
    <visual>
      <origin
        xyz="0 0 0"
        rpy="0 0 0" />
      <geometry>
        <mesh
          filename="../meshes/Altimeter.STL" />
      </geometry>
      <material
        name="S3_Mat">
        <color
          rgba="0.75 0.9 0 1" />
      </material>
    </visual>
  </link>
  <joint
    name="Base_2_A"
    type="fixed">
    <origin
      xyz="0.069067 0 -0.39626"
      rpy="0 0 0" />
    <parent
      link="base_link" />
    <child
      link="Altimeter" />
    <axis
      xyz="0 0 0" />
  </joint>
  <link
    name="A_dial">
    <visual>
      <origin
        xyz="0 0 0"
        rpy="0 0 0" />
      <geometry>
        <mesh
          filename="../meshes/A_dial.STL" />
      </geometry>
      <material
        name="Dial_Mat">
        <color
          rgba="0.79216 0.81961 0.93333 1" />
      </material>
    </visual>
  </link>
  <joint
    name="A_axis"
    type="revolute">
    <origin
      xyz="0 0 0"
      rpy="0 0 0" />
    <parent
      link="Altimeter" />
    <child
      link="A_dial" />
    <axis
      xyz="-1 0 0" />
    <limit
      lower="0"
      upper="5"
      effort="1"
      velocity="1" />
  </joint>
</robot>